<mujoco model="labyrinth">
    <compiler angle="degree"/>
    <option timestep="0.02"/>

    <!-- World -->
    <worldbody>
        <!-- Board -->
        <body name="board" pos="0 0 0.5">
            <inertial pos="0 0 0" mass="5" diaginertia="1 1 1"/>
            <joint name="tilt_x" pos="0 0 0" axis="1 0 0" range="-4 4" damping="0.5"/>
            <joint name="tilt_y" pos="0 0 0" axis="0 1 0" range="-4 4" damping="0.5"/>
            <geom name="board_geom" type="box" size="0.5 0.5 0.01" rgba="0.7 0.7 0.7 1"/>

            <!-- Walls -->
            <geom name="wall_left" type="box" size="0.01 0.5 0.04" pos="-0.49 0 0.05" rgba="255 255 255 1" mass="0"/>
            <geom name="wall_right" type="box" size="0.01 0.5 0.04" pos="0.49 0 0.05" rgba="255 255 255 1" mass="0"/>
            <geom name="wall_top" type="box" size="0.5 0.01 0.04" pos="0 0.49 0.05" rgba="255 255 255 1" mass="0"/>
            <geom name="wall_bottom" type="box" size="0.5 0.01 0.04" pos="0 -0.49 0.05" rgba="255 255 255 1" mass="0"/>
            <geom name="wall_maze1" type="box" size="0.008 0.08 0.04" pos="-0.20 -0.41 0.05" rgba="255 255 255 1"
                  mass="0"/>
            <geom name="wall_maze2" type="box" size="0.008 0.08 0.04" pos="0.15 -0.28 0.05" rgba="255 255 255 1"
                  mass="0"/>
            <geom name="wall_maze3" type="box" size="0.20 0.008 0.04" pos="-0.30 -0.20 0.05" rgba="255 255 255 1"
                  mass="0"/>
            <geom name="wall_maze4" type="box" size="0.15 0.008 0.04" pos="0.20 -0.20 0.05" rgba="255 255 255 1"
                  mass="0"/>
            <geom name="wall_maze5" type="box" size="0.008 0.108 0.04" pos="-0.25 -0.10 0.05" rgba="255 255 255 1"
                  mass="0"/>
            <geom name="wall_maze6" type="box" size="0.008 0.108 0.04" pos="0.05 -0.10 0.05" rgba="255 255 255 1"
                  mass="0"/>
            <geom name="wall_maze7" type="box" size="0.20 0.008 0.04" pos="-0.05 0.0 0.05" rgba="255 255 255 1"
                  mass="0"/>
            <geom name="wall_maze8" type="box" size="0.12 0.008 0.04" pos="0.38 0.0 0.05" rgba="255 255 255 1"
                  mass="0"/>
            <geom name="wall_maze9" type="box" size="0.008 0.20 0.04" pos="-0.37 0.15 0.05" rgba="255 255 255 1"
                  mass="0"/>
            <geom name="wall_maze10" type="box" size="0.008 0.108 0.04" pos="-0.25 0.10 0.05" rgba="255 255 255 1"
                  mass="0"/>
            <geom name="wall_maze11" type="box" size="0.008 0.12 0.04" pos="-0.10 0.23 0.05" rgba="255 255 255 1"
                  mass="0"/>
            <geom name="wall_maze12" type="box" size="0.008 0.108 0.04" pos="0.10 0.25 0.05" rgba="255 255 255 1"
                  mass="0"/>
            <geom name="wall_maze13" type="box" size="0.20 0.008 0.04" pos="0.30 0.15 0.05" rgba="255 255 255 1"
                  mass="0"/>
            <geom name="wall_maze14" type="box" size="0.008 0.108 0.04" pos="0.25 0.35 0.05" rgba="255 255 255 1"
                  mass="0"/>
            <geom name="wall_maze15" type="box" size="0.07 0.008 0.04" pos="0.32 0.30 0.05" rgba="255 255 255 1"
                  mass="0"/>
            <geom name="wall_maze16" type="box" size="0.238 0.008 0.04" pos="-0.14 0.35 0.05" rgba="255 255 255 1"
                  mass="0"/>

            <!-- Sites -->
            <site name="end_goal" pos="0.40 0.40 0.025" type="box" size="0.05 0.05 0.01" rgba="0 0 1 0"/>
        </body>

        <!-- Ball in Lower Left Corner-->
        <body name="ball" pos="-0.40 -0.40 0.58">
            <joint name="free_ball" type="free"/>
            <geom name="ball_geom" type="sphere" size="0.03" mass="0.01" rgba="1 0 0 1"/>
        </body>

        <!-- Camera -->
        <camera name="top_view" pos="0 0 1.75" xyaxes="1 0 0 0 1 0"/>
    </worldbody>

    <!-- Actuators (Instant Tilt) -->
    <actuator>
        <position name="tilt_x_actuator" joint="tilt_x" ctrlrange="-1 1"/>
        <position name="tilt_y_actuator" joint="tilt_y" ctrlrange="-1 1"/>
    </actuator>
</mujoco>